Workbook

Sheet Dashboard
A1: FW26 — MERCHANDISE PLAN DASHBOARD
A2: Auto-populated. Do not edit.
A4: OTB SUMMARY
A5: Metric | B5: Value
A6: Collection | B6: ='OTB Budget'!B4 -> FW26
A7: Total OTB Budget | B7: ='OTB Budget'!B5 -> 500000
A8: Total Planned Retail | B8: ='FW26 Styles'!Q505 -> 0
A9: Total Planned Cost | B9: ='FW26 Styles'!P505 -> 0
A10: Blended Margin % | B10: ='FW26 Styles'!M505 -> 0
A11: Total Units | B11: ='FW26 Styles'!O505 -> 0
A12: Budget Remaining | B12: ='OTB Budget'!B5-'FW26 Styles'!Q505 -> 500000
A13: Last Season Revenue | B13: ='Last Season Data'!N562 -> 3495803.6 | C13: 1 week of sales
A14: Last Season Units | B14: ='Last Season Data'!M562 -> 75457
A16: BY DROP
A17: Drop | B17: OTB ($) | C17: Planned Retail ($) | D17: Planned Cost ($) | E17: Margin % | F17: Units | G17: Remaining ($)
A18: Drop 1 - Sep | B18: ='OTB Budget'!C10 -> 0 | C18: =SUMIFS('FW26 Styles'!Q5:Q574,'FW26 Styles'!I5:I574,A18) -> 0 | D18: =SUMIFS('FW26 Styles'!P5:P574,'FW26 Styles'!I5:I574,A18) -> 0 | E18: =IF(C18=0,"",1-(D18/C18)) | F18: =SUMIFS('FW26 Styles'!O5:O574,'FW26 Styles'!I5:I574,A18) -> 0 | G18: =B18-C18 -> 0
A19: Drop 2 - Oct | B19: ='OTB Budget'!C11 -> 0 | C19: =SUMIFS('FW26 Styles'!Q5:Q574,'FW26 Styles'!I5:I574,A19) -> 0 | D19: =SUMIFS('FW26 Styles'!P5:P574,'FW26 Styles'!I5:I574,A19) -> 0 | E19: =IF(C19=0,"",1-(D19/C19)) | F19: =SUMIFS('FW26 Styles'!O5:O574,'FW26 Styles'!I5:I574,A19) -> 0 | G19: =B19-C19 -> 0
A20: Drop 3 - Nov | B20: ='OTB Budget'!C12 -> 0 | C20: =SUMIFS('FW26 Styles'!Q5:Q574,'FW26 Styles'!I5:I574,A20) -> 0 | D20: =SUMIFS('FW26 Styles'!P5:P574,'FW26 Styles'!I5:I574,A20) -> 0 | E20: =IF(C20=0,"",1-(D20/C20)) | F20: =SUMIFS('FW26 Styles'!O5:O574,'FW26 Styles'!I5:I574,A20) -> 0 | G20: =B20-C20 -> 0
A21: TOTAL | B21: =SUM(B18:B20) -> 0 | C21: =SUM(C18:C20) -> 0 | D21: =SUM(D18:D20) -> 0 | E21: =IF(C21=0,"",1-(D21/C21)) | F21: =SUM(F18:F20) -> 0 | G21: =SUM(G18:G20) -> 0
A23: BY TIER
A24: Tier | B24: Planned Retail ($) | C24: Planned Cost ($) | D24: Margin % | E24: Units | F24: # Styles | G24: % of Total
A25: Trend | B25: =SUMIFS('FW26 Styles'!Q5:Q574,'FW26 Styles'!J5:J574,A25) -> 0 | C25: =SUMIFS('FW26 Styles'!P5:P574,'FW26 Styles'!J5:J574,A25) -> 0 | D25: =IF(B25=0,"",1-(C25/B25)) | E25: =SUMIFS('FW26 Styles'!O5:O574,'FW26 Styles'!J5:J574,A25) -> 0 | F25: =COUNTIF('FW26 Styles'!J5:J574,A25) -> 15 | G25: =IF('FW26 Styles'!Q505=0,"",B25/'FW26 Styles'!Q505) | H25: What is the margin banding for each tier based on the buy contribution
A26: Commercial | B26: =SUMIFS('FW26 Styles'!Q5:Q574,'FW26 Styles'!J5:J574,A26) -> 0 | C26: =SUMIFS('FW26 Styles'!P5:P574,'FW26 Styles'!J5:J574,A26) -> 0 | D26: =IF(B26=0,"",1-(C26/B26)) | E26: =SUMIFS('FW26 Styles'!O5:O574,'FW26 Styles'!J5:J574,A26) -> 0 | F26: =COUNTIF('FW26 Styles'!J5:J574,A26) -> 32 | G26: =IF('FW26 Styles'!Q505=0,"",B26/'FW26 Styles'!Q505) | H26: Price band analysis
A27: Volume | B27: =SUMIFS('FW26 Styles'!Q5:Q574,'FW26 Styles'!J5:J574,A27) -> 0 | C27: =SUMIFS('FW26 Styles'!P5:P574,'FW26 Styles'!J5:J574,A27) -> 0 | D27: =IF(B27=0,"",1-(C27/B27)) | E27: =SUMIFS('FW26 Styles'!O5:O574,'FW26 Styles'!J5:J574,A27) -> 0 | F27: =COUNTIF('FW26 Styles'!J5:J574,A27) -> 0 | G27: =IF('FW26 Styles'!Q505=0,"",B27/'FW26 Styles'!Q505) | H27: Sub 70% margin - Ask the why
A28: TOTAL | B28: =SUM(B25:B27) -> 0 | C28: =SUM(C25:C27) -> 0 | D28: =IF(B28=0,"",1-(C28/B28)) | E28: =SUM(E25:E27) -> 0 | F28: =SUM(F25:F27) -> 47
A30: CATEGORY ROLLUP — PROPOSED vs LAST SEASON
A31: Main Category | B31: Category | C31: Sub Category | D31: Proposed Retail ($) | E31: Proposed Cost ($) | F31: Margin % | G31: Proposed Units | H31: LS Revenue ($) | I31: LS Units | J31: Rev vs LS ($) | K31: Rev vs LS (%) | L31: Units vs LS
A32: Headwear | B32: Scarves | C32: Premium | D32: =SUMIFS('FW26 Styles'!Q5:Q574,'FW26 Styles'!A5:A574,A32,'FW26 Styles'!B5:B574,B32,'FW26 Styles'!C5:C574,C32) -> 0 | E32: =SUMIFS('FW26 Styles'!P5:P574,'FW26 Styles'!A5:A574,A32,'FW26 Styles'!B5:B574,B32,'FW26 Styles'!C5:C574,C32) -> 0 | F32: =IF(D32=0,"",1-(E32/D32)) | G32: =SUMIFS('FW26 Styles'!O5:O574,'FW26 Styles'!A5:A574,A32,'FW26 Styles'!B5:B574,B32,'FW26 Styles'!C5:C574,C32) -> 0 | H32: =SUMIFS('Last Season Data'!N5:N561,'Last Season Data'!B5:B561,A32,'Last Season Data'!C5:C561,B32,'Last Season Data'!D5:D561,C32) -> 566134.71 | I32: =SUMIFS('Last Season Data'!M5:M561,'Last Season Data'!B5:B561,A32,'Last Season Data'!C5:C561,B32,'Last Season Data'!D5:D561,C32) -> 23758 | J32: =D32-H32 -> -566134.71 | K32: =IF(H32=0,"",(D32-H32)/H32) -> -1 | L32: =G32-I32 -> -23758
A33: Headwear | B33: Scarves | C33: Bamboo | D33: =SUMIFS('FW26 Styles'!Q5:Q574,'FW26 Styles'!A5:A574,A33,'FW26 Styles'!B5:B574,B33,'FW26 Styles'!C5:C574,C33) -> 0 | E33: =SUMIFS('FW26 Styles'!P5:P574,'FW26 Styles'!A5:A574,A33,'FW26 Styles'!B5:B574,B33,'FW26 Styles'!C5:C574,C33) -> 0 | F33: =IF(D33=0,"",1-(E33/D33)) | G33: =SUMIFS('FW26 Styles'!O5:O574,'FW26 Styles'!A5:A574,A33,'FW26 Styles'!B5:B574,B33,'FW26 Styles'!C5:C574,C33) -> 0 | H33: =SUMIFS('Last Season Data'!N6:N562,'Last Season Data'!B6:B562,A33,'Last Season Data'!C6:C562,B33,'Last Season Data'!D6:D562,C33) -> 171288.54 | I33: =SUMIFS('Last Season Data'!M5:M561,'Last Season Data'!B5:B561,A33,'Last Season Data'!C5:C561,B33,'Last Season Data'!D5:D561,C33) -> 5230 | J33: =D33-H33 -> -171288.54 | K33: =IF(H33=0,"",(D33-H33)/H33) -> -1 | L33: =G33-I33 -> -5230
A34: Headwear | B34: Scarves | C34: Breathable | D34: =SUMIFS('FW26 Styles'!Q5:Q574,'FW26 Styles'!A5:A574,A34,'FW26 Styles'!B5:B574,B34,'FW26 Styles'!C5:C574,C34) -> 0 | E34: =SUMIFS('FW26 Styles'!P5:P574,'FW26 Styles'!A5:A574,A34,'FW26 Styles'!B5:B574,B34,'FW26 Styles'!C5:C574,C34) -> 0 | F34: =IF(D34=0,"",1-(E34/D34)) | G34: =SUMIFS('FW26 Styles'!O5:O574,'FW26 Styles'!A5:A574,A34,'FW26 Styles'!B5:B574,B34,'FW26 Styles'!C5:C574,C34) -> 0 | H34: =SUMIFS('Last Season Data'!N7:N563,'Last Season Data'!B7:B563,A34,'Last Season Data'!C7:C563,B34,'Last Season Data'!D7:D563,C34) -> 102172.52 | I34: =SUMIFS('Last Season Data'!M5:M561,'Last Season Data'!B5:B561,A34,'Last Season Data'!C5:C561,B34,'Last Season Data'!D5:D561,C34) -> 2723 | J34: =D34-H34 -> -102172.52 | K34: =IF(H34=0,"",(D34-H34)/H34) -> -1 | L34: =G34-I34 -> -2723
A35: Headwear | B35: Scarves | C35: Liquid | D35: =SUMIFS('FW26 Styles'!Q5:Q574,'FW26 Styles'!A5:A574,A35,'FW26 Styles'!B5:B574,B35,'FW26 Styles'!C5:C574,C35) -> 0 | E35: =SUMIFS('FW26 Styles'!P5:P574,'FW26 Styles'!A5:A574,A35,'FW26 Styles'!B5:B574,B35,'FW26 Styles'!C5:C574,C35) -> 0 | F35: =IF(D35=0,"",1-(E35/D35)) | G35: =SUMIFS('FW26 Styles'!O5:O574,'FW26 Styles'!A5:A574,A35,'FW26 Styles'!B5:B574,B35,'FW26 Styles'!C5:C574,C35) -> 0 | H35: =SUMIFS('Last Season Data'!N8:N564,'Last Season Data'!B8:B564,A35,'Last Season Data'!C8:C564,B35,'Last Season Data'!D8:D564,C35) -> 280896.89 | I35: =SUMIFS('Last Season Data'!M5:M561,'Last Season Data'!B5:B561,A35,'Last Season Data'!C5:C561,B35,'Last Season Data'!D5:D561,C35) -> 11742 | J35: =D35-H35 -> -280896.89 | K35: =IF(H35=0,"",(D35-H35)/H35) -> -1 | L35: =G35-I35 -> -11742
A36: Headwear | B36: Scarves | C36: Decorative | D36: =SUMIFS('FW26 Styles'!Q5:Q574,'FW26 Styles'!A5:A574,A36,'FW26 Styles'!B5:B574,B36,'FW26 Styles'!C5:C574,C36) -> 0 | E36: =SUMIFS('FW26 Styles'!P5:P574,'FW26 Styles'!A5:A574,A36,'FW26 Styles'!B5:B574,B36,'FW26 Styles'!C5:C574,C36) -> 0 | F36: =IF(D36=0,"",1-(E36/D36)) | G36: =SUMIFS('FW26 Styles'!O5:O574,'FW26 Styles'!A5:A574,A36,'FW26 Styles'!B5:B574,B36,'FW26 Styles'!C5:C574,C36) -> 0 | H36: =SUMIFS('Last Season Data'!N9:N565,'Last Season Data'!B9:B565,A36,'Last Season Data'!C9:C565,B36,'Last Season Data'!D9:D565,C36) -> 293247.3 | I36: =SUMIFS('Last Season Data'!M5:M561,'Last Season Data'!B5:B561,A36,'Last Season Data'!C5:C561,B36,'Last Season Data'!D5:D561,C36) -> 6195 | J36: =D36-H36 -> -293247.3 | K36: =IF(H36=0,"",(D36-H36)/H36) -> -1 | L36: =G36-I36 -> -6195
A37: Headwear | B37: Scarves | C37: New 1 | D37: =SUMIFS('FW26 Styles'!Q5:Q574,'FW26 Styles'!A5:A574,A37,'FW26 Styles'!B5:B574,B37,'FW26 Styles'!C5:C574,C37) -> 0 | E37: =SUMIFS('FW26 Styles'!P5:P574,'FW26 Styles'!A5:A574,A37,'FW26 Styles'!B5:B574,B37,'FW26 Styles'!C5:C574,C37) -> 0 | F37: =IF(D37=0,"",1-(E37/D37)) | G37: =SUMIFS('FW26 Styles'!O5:O574,'FW26 Styles'!A5:A574,A37,'FW26 Styles'!B5:B574,B37,'FW26 Styles'!C5:C574,C37) -> 0 | H37: =SUMIFS('Last Season Data'!N10:N566,'Last Season Data'!B10:B566,A37,'Last Season Data'!C10:C566,B37,'Last Season Data'!D10:D566,C37) -> 0 | I37: =SUMIFS('Last Season Data'!M5:M561,'Last Season Data'!B5:B561,A37,'Last Season Data'!C5:C561,B37,'Last Season Data'!D5:D561,C37) -> 0 | J37: =D37-H37 -> 0 | K37: =IF(H37=0,"",(D37-H37)/H37) | L37: =G37-I37 -> 0
A38: Headwear | B38: Scarves | C38: New 2 | D38: =SUMIFS('FW26 Styles'!Q5:Q574,'FW26 Styles'!A5:A574,A38,'FW26 Styles'!B5:B574,B38,'FW26 Styles'!C5:C574,C38) -> 0 | E38: =SUMIFS('FW26 Styles'!P5:P574,'FW26 Styles'!A5:A574,A38,'FW26 Styles'!B5:B574,B38,'FW26 Styles'!C5:C574,C38) -> 0 | F38: =IF(D38=0,"",1-(E38/D38)) | G38: =SUMIFS('FW26 Styles'!O5:O574,'FW26 Styles'!A5:A574,A38,'FW26 Styles'!B5:B574,B38,'FW26 Styles'!C5:C574,C38) -> 0 | H38: =SUMIFS('Last Season Data'!N11:N567,'Last Season Data'!B11:B567,A38,'Last Season Data'!C11:C567,B38,'Last Season Data'!D11:D567,C38) -> 0 | I38: =SUMIFS('Last Season Data'!M5:M561,'Last Season Data'!B5:B561,A38,'Last Season Data'!C5:C561,B38,'Last Season Data'!D5:D561,C38) -> 0 | J38: =D38-H38 -> 0 | K38: =IF(H38=0,"",(D38-H38)/H38) | L38: =G38-I38 -> 0
A39: Headwear | B39: Scarves | C39: New 3 | D39: =SUMIFS('FW26 Styles'!Q5:Q574,'FW26 Styles'!A5:A574,A39,'FW26 Styles'!B5:B574,B39,'FW26 Styles'!C5:C574,C39) -> 0 | E39: =SUMIFS('FW26 Styles'!P5:P574,'FW26 Styles'!A5:A574,A39,'FW26 Styles'!B5:B574,B39,'FW26 Styles'!C5:C574,C39) -> 0 | F39: =IF(D39=0,"",1-(E39/D39)) | G39: =SUMIFS('FW26 Styles'!O5:O574,'FW26 Styles'!A5:A574,A39,'FW26 Styles'!B5:B574,B39,'FW26 Styles'!C5:C574,C39) -> 0 | H39: =SUMIFS('Last Season Data'!N12:N568,'Last Season Data'!B12:B568,A39,'Last Season Data'!C12:C568,B39,'Last Season Data'!D12:D568,C39) -> 0 | I39: =SUMIFS('Last Season Data'!M5:M561,'Last Season Data'!B5:B561,A39,'Last Season Data'!C5:C561,B39,'Last Season Data'!D5:D561,C39) -> 0 | J39: =D39-H39 -> 0 | K39: =IF(H39=0,"",(D39-H39)/H39) | L39: =G39-I39 -> 0
B40: Scarves Subtotal | D40: =SUM(D32:D39) -> 0 | E40: =SUM(E32:E39) -> 0 | F40: =IF(D40=0,"",1-(E40/D40)) | G40: =SUM(G32:G39) -> 0 | H40: =SUM(H32:H39) -> 1413740 | I40: =SUM(I32:I39) -> 49648 | J40: =SUM(J32:J39) -> -1413740 | K40: =IF(H40=0,"",(D40-H40)/H40) -> -1 | L40: =SUM(L32:L39) -> -49648
A41: Headwear | B41: Hijab | C41: Premium | D41: =SUMIFS('FW26 Styles'!Q5:Q574,'FW26 Styles'!A5:A574,A41,'FW26 Styles'!B5:B574,B41,'FW26 Styles'!C5:C574,C41) -> 0 | E41: =SUMIFS('FW26 Styles'!P5:P574,'FW26 Styles'!A5:A574,A41,'FW26 Styles'!B5:B574,B41,'FW26 Styles'!C5:C574,C41) -> 0 | F41: =IF(D41=0,"",1-(E41/D41)) | G41: =SUMIFS('FW26 Styles'!O5:O574,'FW26 Styles'!A5:A574,A41,'FW26 Styles'!B5:B574,B41,'FW26 Styles'!C5:C574,C41) -> 0 | H41: =SUMIFS('Last Season Data'!N5:N561,'Last Season Data'!B5:B561,A41,'Last Season Data'!C5:C561,B41,'Last Season Data'!D5:D561,C41) -> 0 | I41: =SUMIFS('Last Season Data'!M5:M561,'Last Season Data'!B5:B561,A41,'Last Season Data'!C5:C561,B41,'Last Season Data'!D5:D561,C41) -> 0 | J41: =D41-H41 -> 0 | K41: =IF(H41=0,"",(D41-H41)/H41) | L41: =G41-I41 -> 0
A42: Headwear | B42: Hijab | C42: Bamboo | D42: =SUMIFS('FW26 Styles'!Q5:Q574,'FW26 Styles'!A5:A574,A42,'FW26 Styles'!B5:B574,B42,'FW26 Styles'!C5:C574,C42) -> 0 | E42: =SUMIFS('FW26 Styles'!P5:P574,'FW26 Styles'!A5:A574,A42,'FW26 Styles'!B5:B574,B42,'FW26 Styles'!C5:C574,C42) -> 0 | F42: =IF(D42=0,"",1-(E42/D42)) | G42: =SUMIFS('FW26 Styles'!O5:O574,'FW26 Styles'!A5:A574,A42,'FW26 Styles'!B5:B574,B42,'FW26 Styles'!C5:C574,C42) -> 0 | H42: =SUMIFS('Last Season Data'!N5:N561,'Last Season Data'!B5:B561,A42,'Last Season Data'!C5:C561,B42,'Last Season Data'!D5:D561,C42) -> 0 | I42: =SUMIFS('Last Season Data'!M5:M561,'Last Season Data'!B5:B561,A42,'Last Season Data'!C5:C561,B42,'Last Season Data'!D5:D561,C42) -> 0 | J42: =D42-H42 -> 0 | K42: =IF(H42=0,"",(D42-H42)/H42) | L42: =G42-I42 -> 0
A43: Headwear | B43: Hijab | C43: Breathable | D43: =SUMIFS('FW26 Styles'!Q5:Q574,'FW26 Styles'!A5:A574,A43,'FW26 Styles'!B5:B574,B43,'FW26 Styles'!C5:C574,C43) -> 0 | E43: =SUMIFS('FW26 Styles'!P5:P574,'FW26 Styles'!A5:A574,A43,'FW26 Styles'!B5:B574,B43,'FW26 Styles'!C5:C574,C43) -> 0 | F43: =IF(D43=0,"",1-(E43/D43)) | G43: =SUMIFS('FW26 Styles'!O5:O574,'FW26 Styles'!A5:A574,A43,'FW26 Styles'!B5:B574,B43,'FW26 Styles'!C5:C574,C43) -> 0 | H43: =SUMIFS('Last Season Data'!N5:N561,'Last Season Data'!B5:B561,A43,'Last Season Data'!C5:C561,B43,'Last Season Data'!D5:D561,C43) -> 0 | I43: =SUMIFS('Last Season Data'!M5:M561,'Last Season Data'!B5:B561,A43,'Last Season Data'!C5:C561,B43,'Last Season Data'!D5:D561,C43) -> 0 | J43: =D43-H43 -> 0 | K43: =IF(H43=0,"",(D43-H43)/H43) | L43: =G43-I43 -> 0
A44: Headwear | B44: Underscarf | C44: Underscarf | D44: =SUMIFS('FW26 Styles'!Q5:Q574,'FW26 Styles'!A5:A574,A44,'FW26 Styles'!B5:B574,B44,'FW26 Styles'!C5:C574,C44) -> 0 | E44: =SUMIFS('FW26 Styles'!P5:P574,'FW26 Styles'!A5:A574,A44,'FW26 Styles'!B5:B574,B44,'FW26 Styles'!C5:C574,C44) -> 0 | F44: =IF(D44=0,"",1-(E44/D44)) | G44: =SUMIFS('FW26 Styles'!O5:O574,'FW26 Styles'!A5:A574,A44,'FW26 Styles'!B5:B574,B44,'FW26 Styles'!C5:C574,C44) -> 0 | H44: =SUMIFS('Last Season Data'!N5:N561,'Last Season Data'!B5:B561,A44,'Last Season Data'!C5:C561,B44,'Last Season Data'!D5:D561,C44) -> 18224.45 | I44: =SUMIFS('Last Season Data'!M5:M561,'Last Season Data'!B5:B561,A44,'Last Season Data'!C5:C561,B44,'Last Season Data'!D5:D561,C44) -> 997 | J44: =D44-H44 -> -18224.45 | K44: =IF(H44=0,"",(D44-H44)/H44) -> -1 | L44: =G44-I44 -> -997
...

Sheet OTB Budget
A1: FW26 — OTB BUDGET & SALES MIX
A2: Set overall OTB, allocate % per drop, then input expected sales mix. Yellow = input.
A4: Collection: | B4: FW26
A5: Total OTB Budget ($): | B5: 500000
A6: Target Margin %: | B6: 0.83
A8: DROP ALLOCATION
A9: Drop | B9: Allocation % | C9: Allocation ($)
A10: Drop 1 - Sep | C10: =B10*B$5 -> 0
A11: Drop 2 - Oct | C11: =B11*B$5 -> 0
A12: Drop 3 - Nov | C12: =B12*B$5 -> 0
A13: TOTAL | B13: =SUM(B10:B12) -> 0 | C13: =SUM(C10:C12) -> 0
A15: PLANNED vs OTB BY DROP
A16: Drop | B16: OTB ($) | C16: Planned Retail ($) | D16: Planned Cost ($) | E16: Planned Units | F16: Remaining ($)
A17: Drop 1 - Sep | B17: =C10 -> 0 | C17: =SUMIFS('FW26 Styles'!Q5:Q504,'FW26 Styles'!I5:I504,A17) -> 0 | D17: =SUMIFS('FW26 Styles'!P5:P504,'FW26 Styles'!I5:I504,A17) -> 0 | E17: =SUMIFS('FW26 Styles'!O5:O504,'FW26 Styles'!I5:I504,A17) -> 0 | F17: =B17-C17 -> 0
A18: Drop 2 - Oct | B18: =C11 -> 0 | C18: =SUMIFS('FW26 Styles'!Q5:Q504,'FW26 Styles'!I5:I504,A18) -> 0 | D18: =SUMIFS('FW26 Styles'!P5:P504,'FW26 Styles'!I5:I504,A18) -> 0 | E18: =SUMIFS('FW26 Styles'!O5:O504,'FW26 Styles'!I5:I504,A18) -> 0 | F18: =B18-C18 -> 0
A19: Drop 3 - Nov | B19: =C12 -> 0 | C19: =SUMIFS('FW26 Styles'!Q5:Q504,'FW26 Styles'!I5:I504,A19) -> 0 | D19: =SUMIFS('FW26 Styles'!P5:P504,'FW26 Styles'!I5:I504,A19) -> 0 | E19: =SUMIFS('FW26 Styles'!O5:O504,'FW26 Styles'!I5:I504,A19) -> 0 | F19: =B19-C19 -> 0
A20: TOTAL | B20: =SUM(B17:B19) -> 0 | C20: =SUM(C17:C19) -> 0 | D20: =SUM(D17:D19) -> 0 | E20: =SUM(E17:E19) -> 0 | F20: =SUM(F17:F19) -> 0
A22: SALES MIX — EXPECTED vs PROPOSED
A23: Main Category | B23: Category | C23: Sub Category | D23: Expected Sales Mix % | E23: Proposed Buy Mix % | F23: Variance (pp)
A24: Headwear | B24: Scarves | C24: Premium | D24: 0.18 | E24: =IF('FW26 Styles'!Q505=0,"",SUMIFS('FW26 Styles'!Q5:Q504,'FW26 Styles'!A5:A504,A24,'FW26 Styles'!B5:B504,B24,'FW26 Styles'!C5:C504,C24)/'FW26 Styles'!Q505) | F24: =IF(OR(D24="",E24=""),"",E24-D24)
A25: Headwear | B25: Scarves | C25: Bamboo | D25: 0.05 | E25: =IF('FW26 Styles'!Q505=0,"",SUMIFS('FW26 Styles'!Q5:Q504,'FW26 Styles'!A5:A504,A25,'FW26 Styles'!B5:B504,B25,'FW26 Styles'!C5:C504,C25)/'FW26 Styles'!Q505) | F25: =IF(OR(D25="",E25=""),"",E25-D25)
A26: Headwear | B26: Scarves | C26: Breathable | D26: 0.03 | E26: =IF('FW26 Styles'!Q505=0,"",SUMIFS('FW26 Styles'!Q5:Q504,'FW26 Styles'!A5:A504,A26,'FW26 Styles'!B5:B504,B26,'FW26 Styles'!C5:C504,C26)/'FW26 Styles'!Q505) | F26: =IF(OR(D26="",E26=""),"",E26-D26)
A27: Headwear | B27: Scarves | C27: Liquid | D27: 0.08 | E27: =IF('FW26 Styles'!Q505=0,"",SUMIFS('FW26 Styles'!Q5:Q504,'FW26 Styles'!A5:A504,A27,'FW26 Styles'!B5:B504,B27,'FW26 Styles'!C5:C504,C27)/'FW26 Styles'!Q505) | F27: =IF(OR(D27="",E27=""),"",E27-D27)
A28: Headwear | B28: Scarves | C28: Decorative | D28: 0.09 | E28: =IF('FW26 Styles'!Q505=0,"",SUMIFS('FW26 Styles'!Q5:Q504,'FW26 Styles'!A5:A504,A28,'FW26 Styles'!B5:B504,B28,'FW26 Styles'!C5:C504,C28)/'FW26 Styles'!Q505) | F28: =IF(OR(D28="",E28=""),"",E28-D28)
A29: Headwear | B29: Scarves | C29: Scarf Gift Box | D29: 0.03 | E29: =IF('FW26 Styles'!Q505=0,"",SUMIFS('FW26 Styles'!Q5:Q504,'FW26 Styles'!A5:A504,A29,'FW26 Styles'!B5:B504,B29,'FW26 Styles'!C5:C504,C29)/'FW26 Styles'!Q505) | F29: =IF(OR(D29="",E29=""),"",E29-D29)
A30: Headwear | B30: Scarves | C30: New 2 | E30: =IF('FW26 Styles'!Q505=0,"",SUMIFS('FW26 Styles'!Q5:Q504,'FW26 Styles'!A5:A504,A30,'FW26 Styles'!B5:B504,B30,'FW26 Styles'!C5:C504,C30)/'FW26 Styles'!Q505) | F30: =IF(OR(D30="",E30=""),"",E30-D30)
A31: Headwear | B31: Scarves | C31: New 3 | E31: =IF('FW26 Styles'!Q505=0,"",SUMIFS('FW26 Styles'!Q5:Q504,'FW26 Styles'!A5:A504,A31,'FW26 Styles'!B5:B504,B31,'FW26 Styles'!C5:C504,C31)/'FW26 Styles'!Q505) | F31: =IF(OR(D31="",E31=""),"",E31-D31)
B32: Scarves Subtotal | D32: =SUM(D24:D31) -> 0.46 | E32: =SUM(E24:E31) -> 0 | F32: =IF(OR(D32="",E32=""),"",E32-D32) -> -0.46
A33: Headwear | B33: Hijab | C33: Premium | E33: =IF('FW26 Styles'!Q505=0,"",SUMIFS('FW26 Styles'!Q5:Q504,'FW26 Styles'!A5:A504,A33,'FW26 Styles'!B5:B504,B33,'FW26 Styles'!C5:C504,C33)/'FW26 Styles'!Q505) | F33: =IF(OR(D33="",E33=""),"",E33-D33)
A34: Headwear | B34: Hijab | C34: Bamboo | E34: =IF('FW26 Styles'!Q505=0,"",SUMIFS('FW26 Styles'!Q5:Q504,'FW26 Styles'!A5:A504,A34,'FW26 Styles'!B5:B504,B34,'FW26 Styles'!C5:C504,C34)/'FW26 Styles'!Q505) | F34: =IF(OR(D34="",E34=""),"",E34-D34)
A35: Headwear | B35: Hijab | C35: Breathable | E35: =IF('FW26 Styles'!Q505=0,"",SUMIFS('FW26 Styles'!Q5:Q504,'FW26 Styles'!A5:A504,A35,'FW26 Styles'!B5:B504,B35,'FW26 Styles'!C5:C504,C35)/'FW26 Styles'!Q505) | F35: =IF(OR(D35="",E35=""),"",E35-D35)
A36: Headwear | B36: Hijab | C36: Underscarf | D36: 0.01 | E36: =IF('FW26 Styles'!Q505=0,"",SUMIFS('FW26 Styles'!Q5:Q504,'FW26 Styles'!A5:A504,A36,'FW26 Styles'!B5:B504,B36,'FW26 Styles'!C5:C504,C36)/'FW26 Styles'!Q505) | F36: =IF(OR(D36="",E36=""),"",E36-D36)
A37: Headwear | B37: Hijab | C37: New 2 | E37: =IF('FW26 Styles'!Q505=0,"",SUMIFS('FW26 Styles'!Q5:Q504,'FW26 Styles'!A5:A504,A37,'FW26 Styles'!B5:B504,B37,'FW26 Styles'!C5:C504,C37)/'FW26 Styles'!Q505) | F37: =IF(OR(D37="",E37=""),"",E37-D37)
A38: Headwear | B38: Hijab | C38: New 3 | E38: =IF('FW26 Styles'!Q505=0,"",SUMIFS('FW26 Styles'!Q5:Q504,'FW26 Styles'!A5:A504,A38,'FW26 Styles'!B5:B504,B38,'FW26 Styles'!C5:C504,C38)/'FW26 Styles'!Q505) | F38: =IF(OR(D38="",E38=""),"",E38-D38)
B39: Hijab Subtotal | D39: =SUM(D33:D38) -> 0.01 | E39: =SUM(E33:E38) -> 0 | F39: =IF(OR(D39="",E39=""),"",E39-D39) -> -0.01
A40: Headwear | B40: Khimaar | C40: Premium | D40: 0.05 | E40: =IF('FW26 Styles'!Q505=0,"",SUMIFS('FW26 Styles'!Q5:Q504,'FW26 Styles'!A5:A504,A40,'FW26 Styles'!B5:B504,B40,'FW26 Styles'!C5:C504,C40)/'FW26 Styles'!Q505) | F40: =IF(OR(D40="",E40=""),"",E40-D40)
A41: Headwear | B41: Khimaar | C41: Bamboo | E41: =IF('FW26 Styles'!Q505=0,"",SUMIFS('FW26 Styles'!Q5:Q504,'FW26 Styles'!A5:A504,A41,'FW26 Styles'!B5:B504,B41,'FW26 Styles'!C5:C504,C41)/'FW26 Styles'!Q505) | F41: =IF(OR(D41="",E41=""),"",E41-D41)
A42: Headwear | B42: Khimaar | C42: Breathable | E42: =IF('FW26 Styles'!Q505=0,"",SUMIFS('FW26 Styles'!Q5:Q504,'FW26 Styles'!A5:A504,A42,'FW26 Styles'!B5:B504,B42,'FW26 Styles'!C5:C504,C42)/'FW26 Styles'!Q505) | F42: =IF(OR(D42="",E42=""),"",E42-D42)
A43: Headwear | B43: Khimaar | C43: New 1 | E43: =IF('FW26 Styles'!Q505=0,"",SUMIFS('FW26 Styles'!Q5:Q504,'FW26 Styles'!A5:A504,A43,'FW26 Styles'!B5:B504,B43,'FW26 Styles'!C5:C504,C43)/'FW26 Styles'!Q505) | F43: =IF(OR(D43="",E43=""),"",E43-D43)
A44: Headwear | B44: Khimaar | C44: New 2 | E44: =IF('FW26 Styles'!Q505=0,"",SUMIFS('FW26 Styles'!Q5:Q504,'FW26 Styles'!A5:A504,A44,'FW26 Styles'!B5:B504,B44,'FW26 Styles'!C5:C504,C44)/'FW26 Styles'!Q505) | F44: =IF(OR(D44="",E44=""),"",E44-D44)
...

Sheet FW26 Styles
A1: FW26 — PRODUCT NOMINATION
A2: One row per style/colour. Assign Drop and Tier. Yellow = input. Margin & totals auto-calculate.
A4: Main Category | B4: Category | C4: Sub Category | D4: Fabric Group | E4: SKU | F4: Style Name | G4: Colour Name | H4: Colour No | I4: Drop | J4: Tier | K4: Cost Price ($) | L4: Retail Price ($) | M4: Margin % | N4: Margin ($) | O4: Units | P4: Total Cost ($) | Q4: Total Retail ($) | R4: Notes
A5: Clothing | B5: Dresses | D5: Branded Knit | F5: High Neck Knit Dress | I5: Drop 1 - Sep | J5: Commercial | K5: 16.016 | L5: 104 | M5: =(L5-K5)/L5 -> 0.846 | N5: =IF(OR($L5="",$K5=""),"",$L5-$K5) -> 87.984 | P5: =IF(OR(O5="",K5=""),"",K5*O5) | Q5: =IF(OR(O5="",L5=""),"",L5*O5)
A6: Clothing | B6: Outerwear | C6: Abaya | D6: Branded Knit | F6: Knitted Abaya | I6: Drop 1 - Sep | J6: Commercial | K6: 18.655 | L6: 119 | M6: =(L6-K6)/L6 -> 0.84323529 | N6: =IF(OR($L6="",$K6=""),"",$L6-$K6) -> 100.345 | P6: =IF(OR(O6="",K6=""),"",K6*O6) | Q6: =IF(OR(O6="",L6=""),"",L6*O6)
A7: Clothing | B7: Tops | C7: Sweater | D7: Branded Knit | F7: Branded Turtle Neck Sweater | I7: Drop 1 - Sep | J7: Commercial | K7: 12.649 | L7: 89 | M7: =(L7-K7)/L7 -> 0.8578764 | N7: =IF(OR($L7="",$K7=""),"",$L7-$K7) -> 76.351 | P7: =IF(OR(O7="",K7=""),"",K7*O7) | Q7: =IF(OR(O7="",L7=""),"",L7*O7)
A8: Clothing | B8: Bottoms | C8: Pants | D8: Branded Knit | F8: Relaxed Fit Knitted Trousers | I8: Drop 1 - Sep | J8: Commercial | K8: 12.285 | L8: 74 | M8: =(L8-K8)/L8 -> 0.83398649 | N8: =IF(OR($L8="",$K8=""),"",$L8-$K8) -> 61.715 | P8: =IF(OR(O8="",K8=""),"",K8*O8) | Q8: =IF(OR(O8="",L8=""),"",L8*O8)
A9: Accessories | B9: Acessories | C9: Hijab | D9: Branded Knit | F9: Knitted Hijab | I9: Drop 1 - Sep | J9: Commercial | K9: 0 | L9: 39 | M9: =(L9-K9)/L9 -> 1 | N9: =IF(OR($L9="",$K9=""),"",$L9-$K9) -> 39 | P9: =IF(OR(O9="",K9=""),"",K9*O9) | Q9: =IF(OR(O9="",L9=""),"",L9*O9)
A10: Clothing | B10: Outerwear | C10: Coat | D10: Bolied Wool | F10: Cape Wrap Coat | I10: Drop 1 - Sep | J10: Commercial | K10: 28.665 | L10: 179 | M10: =(L10-K10)/L10 -> 0.83986034 | N10: =IF(OR($L10="",$K10=""),"",$L10-$K10) -> 150.335 | P10: =IF(OR(O10="",K10=""),"",K10*O10) | Q10: =IF(OR(O10="",L10=""),"",L10*O10)
A11: Clothing | B11: Outerwear | C11: Poncho | D11: Bolied Wool | F11: High Neck Asymmetric Poncho | I11: Drop 1 - Sep | J11: Commercial | K11: 22.295 | L11: 84 | M11: =(L11-K11)/L11 -> 0.73458333 | N11: =IF(OR($L11="",$K11=""),"",$L11-$K11) -> 61.705 | P11: =IF(OR(O11="",K11=""),"",K11*O11) | Q11: =IF(OR(O11="",L11=""),"",L11*O11)
A12: Clothing | B12: Outerwear | C12: Poncho | D12: Bolied Wool | F12: High Neck Poncho | I12: Drop 1 - Sep | J12: Commercial | K12: 22.568 | L12: 84 | M12: =(L12-K12)/L12 -> 0.73133333 | N12: =IF(OR($L12="",$K12=""),"",$L12-$K12) -> 61.432 | P12: =IF(OR(O12="",K12=""),"",K12*O12) | Q12: =IF(OR(O12="",L12=""),"",L12*O12)
A13: Clothing | B13: Bottoms | C13: Skirt | D13: Bolied Wool | F13: Wool Volume Skirt | I13: Drop 1 - Sep | J13: Commercial | K13: 18.655 | L13: 74 | M13: =(L13-K13)/L13 -> 0.74790541 | N13: =IF(OR($L13="",$K13=""),"",$L13-$K13) -> 55.345 | P13: =IF(OR(O13="",K13=""),"",K13*O13) | Q13: =IF(OR(O13="",L13=""),"",L13*O13)
A14: Clothing | B14: Dresses | D14: Cotton Jersey | F14: Volume Cotton Tee Dress | I14: Drop 1 - Sep | J14: Commercial | K14: 16.107 | L14: 79 | M14: =(L14-K14)/L14 -> 0.79611392 | N14: =IF(OR($L14="",$K14=""),"",$L14-$K14) -> 62.893 | P14: =IF(OR(O14="",K14=""),"",K14*O14) | Q14: =IF(OR(O14="",L14=""),"",L14*O14)
A15: Clothing | B15: Tops | C15: LS Tee | D15: Cotton Jersey | F15: Volume Cotton Tee | I15: Drop 1 - Sep | J15: Commercial | K15: 17.108 | L15: 59 | M15: =(L15-K15)/L15 -> 0.7100339 | N15: =IF(OR($L15="",$K15=""),"",$L15-$K15) -> 41.892 | P15: =IF(OR(O15="",K15=""),"",K15*O15) | Q15: =IF(OR(O15="",L15=""),"",L15*O15)
A16: Clothing | B16: Bottoms | C16: Pants | D16: Cotton Jersey | F16: Jersey Tailored Pants | I16: Drop 1 - Sep | J16: Commercial | K16: 12.6945 | L16: 69 | M16: =(L16-K16)/L16 -> 0.81602174 | N16: =IF(OR($L16="",$K16=""),"",$L16-$K16) -> 56.3055 | P16: =IF(OR(O16="",K16=""),"",K16*O16) | Q16: =IF(OR(O16="",L16=""),"",L16*O16)
A17: Clothing | B17: Outerwear | C17: Jacket | D17: Satin | F17: Satin Baloon Jackt | I17: Drop 1 - Sep | J17: Commercial | K17: 18.473 | L17: 98 | M17: =(L17-K17)/L17 -> 0.8115 | N17: =IF(OR($L17="",$K17=""),"",$L17-$K17) -> 79.527 | P17: =IF(OR(O17="",K17=""),"",K17*O17) | Q17: =IF(OR(O17="",L17=""),"",L17*O17)
A18: Clothing | B18: Bottoms | C18: Pants | D18: Satin | F18: Airy Wide Fit | I18: Drop 1 - Sep | J18: Commercial | K18: 12.467 | L18: 79 | M18: =(L18-K18)/L18 -> 0.84218987 | N18: =IF(OR($L18="",$K18=""),"",$L18-$K18) -> 66.533 | P18: =IF(OR(O18="",K18=""),"",K18*O18) | Q18: =IF(OR(O18="",L18=""),"",L18*O18)
A19: Clothing | B19: Outerwear | C19: Jacket | D19: Tailored Biker Sets | F19: Woven Biker Jacket Op1 | I19: Drop 1 - Sep | J19: Trend | K19: 27.755 | L19: 129 | M19: =(L19-K19)/L19 -> 0.78484496 | N19: =IF(OR($L19="",$K19=""),"",$L19-$K19) -> 101.245 | P19: =IF(OR(O19="",K19=""),"",K19*O19) | Q19: =IF(OR(O19="",L19=""),"",L19*O19)
A20: Clothing | B20: Outerwear | C20: Jacket | D20: Tailored Biker Sets | F20: Woven Biker Jacket Op2 | I20: Drop 1 - Sep | J20: Trend | K20: 24.479 | L20: 129 | M20: =(L20-K20)/L20 -> 0.81024031 | N20: =IF(OR($L20="",$K20=""),"",$L20-$K20) -> 104.521 | P20: =IF(OR(O20="",K20=""),"",K20*O20) | Q20: =IF(OR(O20="",L20=""),"",L20*O20)
A21: Clothing | B21: Dresses | D21: Tailored Biker Sets | F21: Front Zip Dress | I21: Drop 1 - Sep | J21: Commercial | K21: 21.203 | L21: 109 | M21: =(L21-K21)/L21 -> 0.80547706 | N21: =IF(OR($L21="",$K21=""),"",$L21-$K21) -> 87.797 | P21: =IF(OR(O21="",K21=""),"",K21*O21) | Q21: =IF(OR(O21="",L21=""),"",L21*O21)
A22: Clothing | B22: Bottoms | C22: Skirt | D22: Tailored Biker Sets | F22: Tailored Flared Skirt | I22: Drop 1 - Sep | J22: Commercial | K22: 18.018 | L22: 74 | M22: =(L22-K22)/L22 -> 0.75651351 | N22: =IF(OR($L22="",$K22=""),"",$L22-$K22) -> 55.982 | P22: =IF(OR(O22="",K22=""),"",K22*O22) | Q22: =IF(OR(O22="",L22=""),"",L22*O22)
A23: Clothing | B23: Bottoms | C23: Pants | D23: Tailored Biker Sets | F23: Relaxed Fit Trousers | I23: Drop 1 - Sep | J23: Commercial | K23: 14.469 | L23: 74 | M23: =(L23-K23)/L23 -> 0.80447297 | N23: =IF(OR($L23="",$K23=""),"",$L23-$K23) -> 59.531 | P23: =IF(OR(O23="",K23=""),"",K23*O23) | Q23: =IF(OR(O23="",L23=""),"",L23*O23)
A24: Clothing | B24: Outerwear | C24: Jacket | D24: Tailored Biker Sets | F24: Woven Biker Jacket | I24: Drop 1 - Sep | J24: Trend | K24: 18.6641 | L24: 129 | M24: =(L24-K24)/L24 -> 0.85531705 | N24: =IF(OR($L24="",$K24=""),"",$L24-$K24) -> 110.3359 | P24: =IF(OR(O24="",K24=""),"",K24*O24) | Q24: =IF(OR(O24="",L24=""),"",L24*O24)
A25: Clothing | B25: Dresses | D25: Tailored Biker Sets | F25: Front Zip Dress | I25: Drop 1 - Sep | J25: Commercial | K25: 16.8896 | L25: 109 | M25: =(L25-K25)/L25 -> 0.84504954 | N25: =IF(OR($L25="",$K25=""),"",$L25-$K25) -> 92.1104 | P25: =IF(OR(O25="",K25=""),"",K25*O25) | Q25: =IF(OR(O25="",L25=""),"",L25*O25)
A26: Clothing | B26: Bottoms | C26: Skirt | D26: Tailored Biker Sets | F26: Tailored Flared Skirt | I26: Drop 1 - Sep | J26: Commercial | K26: 13.4225 | L26: 74 | M26: =(L26-K26)/L26 -> 0.81861486 | N26: =IF(OR($L26="",$K26=""),"",$L26-$K26) -> 60.5775 | P26: =IF(OR(O26="",K26=""),"",K26*O26) | Q26: =IF(OR(O26="",L26=""),"",L26*O26)
A27: Clothing | B27: Bottoms | C27: Pants | D27: Tailored Biker Sets | F27: Relaxed Fit Trousers | I27: Drop 1 - Sep | J27: Commercial | K27: 11.3568 | L27: 74 | M27: =(L27-K27)/L27 -> 0.84652973 | N27: =IF(OR($L27="",$K27=""),"",$L27-$K27) -> 62.6432 | P27: =IF(OR(O27="",K27=""),"",K27*O27) | Q27: =IF(OR(O27="",L27=""),"",L27*O27)
A28: Clothing | B28: Outerwear | C28: Jacket | D28: Tweed | F28: Tweed Bomber Jacket | I28: Drop 1 - Sep | J28: Commercial | K28: 27.755 | L28: 129 | M28: =(L28-K28)/L28 -> 0.78484496 | N28: =IF(OR($L28="",$K28=""),"",$L28-$K28) -> 101.245 | P28: =IF(OR(O28="",K28=""),"",K28*O28) | Q28: =IF(OR(O28="",L28=""),"",L28*O28)
A29: Clothing | B29: Dresses | D29: Tweed | F29: Tweed Volume Dress | I29: Drop 1 - Sep | J29: Commercial | K29: 16.289 | L29: 109 | M29: =(L29-K29)/L29 -> 0.85055963 | N29: =IF(OR($L29="",$K29=""),"",$L29-$K29) -> 92.711 | P29: =IF(OR(O29="",K29=""),"",K29*O29) | Q29: =IF(OR(O29="",L29=""),"",L29*O29)
A30: Clothing | B30: Bottoms | C30: Skirt | D30: Tweed | F30: Tweed Skirt Opt1 | I30: Drop 1 - Sep | J30: Commercial | K30: 16.926 | L30: 74 | M30: =(L30-K30)/L30 -> 0.77127027 | N30: =IF(OR($L30="",$K30=""),"",$L30-$K30) -> 57.074 | P30: =IF(OR(O30="",K30=""),"",K30*O30) | Q30: =IF(OR(O30="",L30=""),"",L30*O30)
A31: Clothing | B31: Bottoms | C31: Skirt | D31: Tweed | F31: Tweed Skirt Opt2 | I31: Drop 1 - Sep | J31: Commercial | K31: 27.209 | L31: 74 | M31: =(L31-K31)/L31 -> 0.63231081 | N31: =IF(OR($L31="",$K31=""),"",$L31-$K31) -> 46.791 | P31: =IF(OR(O31="",K31=""),"",K31*O31) | Q31: =IF(OR(O31="",L31=""),"",L31*O31)
A32: Clothing | B32: Outerwear | C32: Jacket | D32: Tweed | F32: Tweed Bomber Jacket | I32: Drop 1 - Sep | J32: Trend | K32: 23.023 | L32: 129 | M32: =(L32-K32)/L32 -> 0.82152713 | N32: =IF(OR($L32="",$K32=""),"",$L32-$K32) -> 105.977 | P32: =IF(OR(O32="",K32=""),"",K32*O32) | Q32: =IF(OR(O32="",L32=""),"",L32*O32)
A33: Clothing | B33: Bottoms | C33: Skirt | D33: Tweed | F33: Tweed Skirt | I33: Drop 1 - Sep | J33: Trend | K33: 15.925 | L33: 74 | M33: =(L33-K33)/L33 -> 0.7847973 | N33: =IF(OR($L33="",$K33=""),"",$L33-$K33) -> 58.075 | P33: =IF(OR(O33="",K33=""),"",K33*O33) | Q33: =IF(OR(O33="",L33=""),"",L33*O33)
A34: Clothing | B34: Bottoms | C34: Skirt | D34: Tweed | F34: Tweed Skirt Opt2 | I34: Drop 1 - Sep | J34: Trend | K34: 15.925 | L34: 74 | M34: =(L34-K34)/L34 -> 0.7847973 | N34: =IF(OR($L34="",$K34=""),"",$L34-$K34) -> 58.075 | P34: =IF(OR(O34="",K34=""),"",K34*O34) | Q34: =IF(OR(O34="",L34=""),"",L34*O34)
A35: Clothing | B35: Dresses | D35: Tweed | F35: Tweed Volume Dress | I35: Drop 1 - Sep | K35: 31.85 | L35: 109 | M35: =(L35-K35)/L35 -> 0.70779817 | N35: =IF(OR($L35="",$K35=""),"",$L35-$K35) -> 77.15 | P35: =IF(OR(O35="",K35=""),"",K35*O35) | Q35: =IF(OR(O35="",L35=""),"",L35*O35)
A36: Clothing | B36: Dresses | D36: Draped Knit | F36: Draped Knit Dress | I36: Drop 1 - Sep | K36: 19.565 | L36: 109 | M36: =(L36-K36)/L36 -> 0.82050459 | N36: =IF(OR($L36="",$K36=""),"",$L36-$K36) -> 89.435 | P36: =IF(OR(O36="",K36=""),"",K36*O36) | Q36: =IF(OR(O36="",L36=""),"",L36*O36)
A37: Clothing | B37: Tops | D37: Draped Knit | F37: Draped Layered Top | I37: Drop 1 - Sep | K37: 12.649 | L37: 79 | M37: =(L37-K37)/L37 -> 0.83988608 | N37: =IF(OR($L37="",$K37=""),"",$L37-$K37) -> 66.351 | P37: =IF(OR(O37="",K37=""),"",K37*O37) | Q37: =IF(OR(O37="",L37=""),"",L37*O37)
A38: Clothing | B38: Bottoms | C38: Skirt | D38: Draped Knit | F38: Maxi Flared Skirt | I38: Drop 1 - Sep | K38: 10.92 | L38: 69 | M38: =(L38-K38)/L38 -> 0.84173913 | N38: =IF(OR($L38="",$K38=""),"",$L38-$K38) -> 58.08 | P38: =IF(OR(O38="",K38=""),"",K38*O38) | Q38: =IF(OR(O38="",L38=""),"",L38*O38)
A39: Accessories | B39: Acessories | C39: Hijab | D39: Draped Knit | F39: Knitted Hijab | I39: Drop 1 - Sep | K39: 4.6501 | L39: 29 | M39: =(L39-K39)/L39 -> 0.83965172 | N39: =IF(OR($L39="",$K39=""),"",$L39-$K39) -> 24.3499 | P39: =IF(OR(O39="",K39=""),"",K39*O39) | Q39: =IF(OR(O39="",L39=""),"",L39*O39)
A40: Clothing | B40: Outerwear | C40: Blazer | D40: Signature Tailoring | F40: Loose Fit Blazer | I40: Drop 1 - Sep | K40: 27.755 | L40: 109 | M40: =(L40-K40)/L40 -> 0.74536697 | N40: =IF(OR($L40="",$K40=""),"",$L40-$K40) -> 81.245 | P40: =IF(OR(O40="",K40=""),"",K40*O40) | Q40: =IF(OR(O40="",L40=""),"",L40*O40)
A41: Clothing | B41: Bottoms | C41: Skirt | D41: Signature Tailoring | F41: Tailored Volume Skirt | I41: Drop 1 - Sep | K41: 14.105 | L41: 74 | M41: =(L41-K41)/L41 -> 0.80939189 | N41: =IF(OR($L41="",$K41=""),"",$L41-$K41) -> 59.895 | P41: =IF(OR(O41="",K41=""),"",K41*O41) | Q41: =IF(OR(O41="",L41=""),"",L41*O41)
...

Sheet Last Season Data
B1: LAST SEASON — RAW DATA
B2: Paste last season data here. Ensure Main Category/Category/Sub Category match your current structure. Yellow = input.
A4: Drop | B4: Main Category | C4: Category | D4: Sub Category | E4: Fabric Group | F4: SKU | G4: Style Name | H4: Colour Name | I4: Colour Code | J4: Retail Price ($) | K4: Cost Price ($) | L4: Buy Qty | M4: Sales Units | N4: Sales Revenue ($) | O4: Margin %
A5: Drop 1 | B5: Headwear | C5: Scarves | D5: Premium | E5: Premium Jersey | F5: 23-2-FA23-8 | G5: Premium Jersey Scarf | H5: Chocolate | I5: 131 | J5: 25 | K5: 3.77 | L5: 3000 | M5: 2593 | N5: 61089.31 | O5: =IF(OR(N5="",N5=0),"",(N5-(K5*M5))/N5) -> 0.83997839
A6: Drop 1 | B6: Headwear | C6: Scarves | D6: Premium | E6: Premium Jersey | F6: 23-2-FA23-8 | G6: Premium Jersey Scarf | H6: Ash Brown | I6: 469 | J6: 25 | K6: 3.77 | L6: 3000 | M6: 2311 | N6: 54879.86 | O6: =IF(OR(N6="",N6=0),"",(N6-(K6*M6))/N6) -> 0.84124468
A7: Drop 1 | B7: Clothing | C7: Tops | D7: Sweater | E7: Comfy | F7: 25-2-FA25-5 | G7: Comfy Hoodie | H7: Chocolate | I7: 131 | J7: 79 | K7: 16.9 | L7: 1080 | M7: 623 | N7: 48996.43 | O7: =IF(OR(N7="",N7=0),"",(N7-(K7*M7))/N7) -> 0.78511292
A8: Drop 1 | B8: Clothing | C8: Outerwear | D8: Coat | E8: Double Wool Thick | F8: 25-1-FA25-19 | G8: Wool Blend Abaya | H8: Dark Brown | I8: 162 | J8: 139 | K8: 25 | L8: 360 | M8: 339 | N8: 46449.37 | O8: =IF(OR(N8="",N8=0),"",(N8-(K8*M8))/N8) -> 0.81754327
A9: Drop 1 | B9: Clothing | C9: Outerwear | D9: Bomber | E9: Neoprene | F9: 24-2-FA24-4 | G9: Neoprene Bomber | H9: Dark Cherry | I9: 439 | J9: 99 | K9: 19.5 | L9: 624 | M9: 455 | N9: 44753.52 | O9: =IF(OR(N9="",N9=0),"",(N9-(K9*M9))/N9) -> 0.80174744
A10: Drop 1 | B10: Clothing | C10: Outerwear | D10: Blazer | E10: Fall Tailoring | F10: 25-1-FA25-4 | G10: Tailored Oversized Blazer | H10: Dark Brown | I10: 162 | J10: 109 | K10: 17.5 | L10: 504 | M10: 386 | N10: 41770.58 | O10: =IF(OR(N10="",N10=0),"",(N10-(K10*M10))/N10) -> 0.83828331
A11: Drop 1 | B11: Headwear | C11: Scarves | D11: Liquid | E11: Liquid Jersey | F11: 24-2-SU24-6 | G11: Liquid Jersey Scarf | H11: Dark Brown | I11: 162 | J11: 25 | K11: 3.63 | L11: 1800 | M11: 1810 | N11: 41357.95 | O11: =IF(OR(N11="",N11=0),"",(N11-(K11*M11))/N11) -> 0.84113574
A12: Drop 1 | B12: Clothing | C12: Outerwear | D12: Coat | E12: Classic Soft Tailoring | F12: 25-1-FA25-11 | G12: Trench Abaya | H12: Dark Brown | I12: 162 | J12: 149 | K12: 28 | L12: 300 | M12: 274 | N12: 40695.6 | O12: =IF(OR(N12="",N12=0),"",(N12-(K12*M12))/N12) -> 0.81147839
A13: Drop 1 | B13: Clothing | C13: Outerwear | D13: Bomber | E13: Neoprene | F13: 24-2-FA24-4 | G13: Neoprene Bomber | H13: Black | I13: 100 | J13: 99 | K13: 19.5 | L13: 624 | M13: 410 | N13: 40604.97 | O13: =IF(OR(N13="",N13=0),"",(N13-(K13*M13))/N13) -> 0.80310292
A14: Drop 1 | B14: Clothing | C14: Dresses | D14: Casual | E14: Rib Knit | F14: 25-3-FA25-10 | G14: Ribbed Knit Dress | H14: Khaki | I14: 374 | J14: 129 | K14: 13.5 | L14: 528 | M14: 313 | N14: 40390.47 | O14: =IF(OR(N14="",N14=0),"",(N14-(K14*M14))/N14) -> 0.89538374
A15: Drop 1 | B15: Headwear | C15: Scarves | D15: Premium | E15: Premium Jersey | F15: 23-2-FA23-8 | G15: Premium Jersey Scarf | H15: Marron | I15: 452 | J15: 25 | K15: 3.77 | L15: 3000 | M15: 1609 | N15: 38503.2 | O15: =IF(OR(N15="",N15=0),"",(N15-(K15*M15))/N15) -> 0.84245647
A16: Drop 1 | B16: Clothing | C16: Dresses | D16: Essential | E16: Textured Jersey | F16: 23-2-FA23-12 | G16: Essential Jersey Dress Regular | H16: Dark Brown | I16: 162 | J16: 89 | K16: 10.11 | L16: 700 | M16: 422 | N16: 37041.11 | O16: =IF(OR(N16="",N16=0),"",(N16-(K16*M16))/N16) -> 0.88481933
... A561: Drop 2 | B561: Clothing | C561: Bottoms | D561: Pants | E561: Cotton | F561: 25-2-FA25-18 | G561: The Casual Pants | H561: Black | I561: 100 | J561: 69 | K561: 13.3 | L561: 0 | M561: 0 | N561: 0 | O561: =IF(OR(N561="",N561=0),"",(N561-(K561*M561))/N561)
L562: =SUM(L3:L561) -> 375718 | M562: =SUM(M3:M561) -> 75457 | N562: =SUM(N3:N561) -> 3495803.6

Sheet Sheet1
A1: Main Category | B1: Category | C1: Sub Category | D1: Total Sales U | E1: Total Rev | F1: U Mix % | G1: Sales Mix % | H1: U Buy Mix %
A2: Accessories | B2: Accessories | C2: Bags | D2: 264 | E2: 17724.92 | F2: 0.0034986814 | G2: 0.0050703421 | H2: 0.0063877696
A3: Accessories | B3: Accessories | C3: Balaclava | D3: 212 | E3: 7984.41 | F3: 0.0028095472 | G3: 0.0022839984 | H3: 0.0017300209
A4: Accessories | B4: Accessories | C4: Gloves | D4: 167 | E4: 6318 | F4: 0.002213181 | G4: 0.0018073098 | H4: 0.0017300209
A5: Accessories | B5: Accessories | C5: Hijab Pins | D5: 345 | E5: 6295.66 | F5: 0.0045721404 | G5: 0.0018009193 | H5: 0.0053231413
A6: Accessories | B6: Accessories | C6: Scarf | D6: 691 | E6: 39389.62 | F6: 0.0091575334 | G6: 0.011267687 | H6: 0.010992287
A7: Accessories | B7: Accessories | C7: Tote Bags | D7: 1409 | E7: 44310.47 | F7: 0.018672887 | G7: 0.012675332 | H7: 0.017832523
A8: Accessories | B8: Accessories Total | D8: 3088 | E8: 122023.08 | F8: 0.04092397 | G8: 0.034905588 | H8: 0.043995763
A9: Accessories Total | D9: 3088 | E9: 122023.08 | F9: 0.04092397 | G9: 0.034905588 | H9: 0.043995763
A10: Clothing | B10: Bottoms | C10: Leggings | D10: 379 | E10: 16808.41 | F10: 0.0050227282 | G10: 0.0048081677 | H10: 0.020653788
A11: Clothing | B11: Bottoms | C11: Pants | D11: 2739 | E11: 209084.69 | F11: 0.036298819 | G11: 0.059810194 | H11: 0.043724283
A12: Clothing | B12: Bottoms | C12: Skirts | D12: 1042 | E12: 84427.79 | F12: 0.013809189 | G12: 0.024151182 | H12: 0.017917694
A13: Clothing | B13: Bottoms Total | D13: 4160 | E13: 310320.89 | F13: 0.055130737 | G13: 0.088769544 | H13: 0.082295764
A14: Clothing | B14: Dresses | C14: Casual | D14: 3424 | E14: 353219.3 | F14: 0.045376837 | G14: 0.10104095 | H14: 0.066608467
A15: Clothing | B15: Dresses | C15: Essential | D15: 1452 | E15: 128725.15 | F15: 0.019242748 | G15: 0.036822764 | H15: 0.0471098
A16: Clothing | B16: Dresses | C16: Occasion | D16: 254 | E16: 30277.18 | F16: 0.0033661556 | G16: 0.0086610072 | H16: 0.0068349134
A17: Clothing | B17: Dresses Total | D17: 5130 | E17: 512221.63 | F17: 0.06798574 | G17: 0.14652472 | H17: 0.12055318
A18: Clothing | B18: Outerwear | C18: Abaya | D18: 618 | E18: 80161.29 | F18: 0.008190095 | G18: 0.022930719 | H18: 0.012243225
A19: Clothing | B19: Outerwear | C19: Blazer | D19: 717 | E19: 77868.15 | F19: 0.0095021005 | G19: 0.02227475 | H19: 0.0089428774
A20: Clothing | B20: Outerwear | C20: Bomber | D20: 1766 | E20: 184962.19 | F20: 0.023404058 | G20: 0.052909777 | H20: 0.014308604
A21: Clothing | B21: Outerwear | C21: Cape | D21: 507 | E21: 19464.95 | F21: 0.0067190585 | G21: 0.0055680903 | H21: 0.0027467409
A22: Clothing | B22: Outerwear | C22: Coat | D22: 1742 | E22: 240936.79 | F22: 0.023085996 | G22: 0.068921718 | H22: 0.023586839
A23: Clothing | B23: Outerwear | C23: Jacket | D23: 570 | E23: 53526.62 | F23: 0.0075539711 | G23: 0.015311678 | H23: 0.0063877696
A24: Clothing | B24: Outerwear | C24: Poncho | D24: 198 | E24: 12356.86 | F24: 0.002624011 | G24: 0.0035347695 | H24: 0.0016288812
A25: Clothing | B25: Outerwear Total | D25: 6118 | E25: 669276.85 | F25: 0.08107929 | G25: 0.1914515 | H25: 0.069844937
A26: Clothing | B26: Tops | C26: Cardigan | D26: 552 | E26: 48982.45 | F26: 0.0073154247 | G26: 0.014011785 | H26: 0.0053018487
A27: Clothing | B27: Tops | C27: LS Top | D27: 2116 | E27: 123510.22 | F27: 0.028042461 | G27: 0.035330995 | H27: 0.022101683
A28: Clothing | B28: Tops | C28: Shirt | D28: 473 | E28: 39192.49 | F28: 0.0062684708 | G28: 0.011211296 | H28: 0.0090706328
A29: Clothing | B29: Tops | C29: Sweater | D29: 2606 | E29: 217169.61 | F29: 0.034536226 | G29: 0.062122944 | H29: 0.037176819
A30: Clothing | B30: Tops Total | D30: 5747 | E30: 428854.77 | F30: 0.076162583 | G30: 0.12267702 | H30: 0.073650983
A31: Clothing Total | D31: 21155 | E31: 1920674.1 | F31: 0.28035835 | G31: 0.54942278 | H31: 0.34634487
A32: Headwear | B32: Scarves | C32: Bamboo | D32: 5230 | E32: 171288.54 | F32: 0.069310998 | G32: 0.04899833 | H32: 0.11900415
A33: Headwear | B33: Scarves | C33: Breathable | D33: 2723 | E33: 102172.52 | F33: 0.036086778 | G33: 0.029227191 | H33: 0.027765505
A34: Headwear | B34: Scarves | C34: Decorative | D34: 6195 | E34: 293247.3 | F34: 0.082099739 | G34: 0.083885519 | H34: 0.054296041
A35: Headwear | B35: Scarves | C35: Liquid | D35: 11742 | E35: 280896.89 | F35: 0.15561181 | G35: 0.080352595 | H35: 0.10635636
A36: Headwear | B36: Scarves | C36: Modal | D36: 569 | E36: 21141.97 | F36: 0.0075407186 | G36: 0.006047814 | H36: 0.018630995
A37: Headwear | B37: Scarves | C37: Premium | D37: 23758 | E37: 566134.71 | F37: 0.31485482 | G37: 0.16194694 | H37: 0.26683843
A38: Headwear | B38: Scarves Total | D38: 50217 | E38: 1434881.9 | F38: 0.66550486 | G38: 0.41045839 | H38: 0.59289148
A39: Headwear | B39: Underscarf | C39: Underscarf | D39: 997 | E39: 18224.45 | F39: 0.013212823 | G39: 0.0052132362 | H39: 0.016767895
A40: Headwear | B40: Underscarf Total | D40: 997 | E40: 18224.45 | F40: 0.013212823 | G40: 0.0052132362 | H40: 0.016767895
...

Sheet Sign Off
A1: FW26 — MERCH PLAN SIGN OFF
A2: Proposed Plan vs Final Buy. Yellow = Final Buy inputs.
A4: OVERALL SUMMARY
B5: Proposed Plan | C5: Final Buy | D5: Variance ($) | E5: Variance (%)
A6: OTB Budget | B6: ='OTB Budget'!B5 -> 500000 | D6: =IF(C6="","",C6-B6) | E6: =IF(OR(C6="",B6=0),"",(C6-B6)/B6)
A7: Total Retail | B7: ='FW26 Styles'!Q505 -> 0 | D7: =IF(C7="","",C7-B7) | E7: =IF(OR(C7="",B7=0),"",(C7-B7)/B7)
A8: Total Cost | B8: ='FW26 Styles'!P505 -> 0 | D8: =IF(C8="","",C8-B8) | E8: =IF(OR(C8="",B8=0),"",(C8-B8)/B8)
A9: Blended Margin % | B9: ='FW26 Styles'!M505 -> 0 | D9: =IF(C9="","",C9-B9)
A10: Total Units | B10: ='FW26 Styles'!O505 -> 0 | D10: =IF(C10="","",C10-B10) | E10: =IF(OR(C10="",B10=0),"",(C10-B10)/B10)
A13: BY CATEGORY: PROPOSED vs FINAL BUY
A14: Main Category | B14: Category | C14: Sub Category | D14: Proposed Retail ($) | E14: Proposed Cost ($) | F14: Proposed Margin % | G14: Proposed Units | H14: Final Retail ($) | I14: Final Cost ($) | J14: Final Margin % | K14: Final Units
A15: Headwear | B15: Scarves | C15: Premium | D15: =SUMIFS('FW26 Styles'!Q5:Q504,'FW26 Styles'!A5:A504,A15,'FW26 Styles'!B5:B504,B15,'FW26 Styles'!C5:C504,C15) -> 0 | E15: =SUMIFS('FW26 Styles'!P5:P504,'FW26 Styles'!A5:A504,A15,'FW26 Styles'!B5:B504,B15,'FW26 Styles'!C5:C504,C15) -> 0 | F15: =IF(D15=0,"",1-(E15/D15)) | G15: =SUMIFS('FW26 Styles'!O5:O504,'FW26 Styles'!A5:A504,A15,'FW26 Styles'!B5:B504,B15,'FW26 Styles'!C5:C504,C15) -> 0 | J15: =IF(H15=0,"",1-(I15/H15))
A16: Headwear | B16: Scarves | C16: Bamboo | D16: =SUMIFS('FW26 Styles'!Q5:Q504,'FW26 Styles'!A5:A504,A16,'FW26 Styles'!B5:B504,B16,'FW26 Styles'!C5:C504,C16) -> 0 | E16: =SUMIFS('FW26 Styles'!P5:P504,'FW26 Styles'!A5:A504,A16,'FW26 Styles'!B5:B504,B16,'FW26 Styles'!C5:C504,C16) -> 0 | F16: =IF(D16=0,"",1-(E16/D16)) | G16: =SUMIFS('FW26 Styles'!O5:O504,'FW26 Styles'!A5:A504,A16,'FW26 Styles'!B5:B504,B16,'FW26 Styles'!C5:C504,C16) -> 0 | J16: =IF(H16=0,"",1-(I16/H16))
A17: Headwear | B17: Scarves | C17: Breathable | D17: =SUMIFS('FW26 Styles'!Q5:Q504,'FW26 Styles'!A5:A504,A17,'FW26 Styles'!B5:B504,B17,'FW26 Styles'!C5:C504,C17) -> 0 | E17: =SUMIFS('FW26 Styles'!P5:P504,'FW26 Styles'!A5:A504,A17,'FW26 Styles'!B5:B504,B17,'FW26 Styles'!C5:C504,C17) -> 0 | F17: =IF(D17=0,"",1-(E17/D17)) | G17: =SUMIFS('FW26 Styles'!O5:O504,'FW26 Styles'!A5:A504,A17,'FW26 Styles'!B5:B504,B17,'FW26 Styles'!C5:C504,C17) -> 0 | J17: =IF(H17=0,"",1-(I17/H17))
A18: Headwear | B18: Scarves | C18: Liquid | D18: =SUMIFS('FW26 Styles'!Q5:Q504,'FW26 Styles'!A5:A504,A18,'FW26 Styles'!B5:B504,B18,'FW26 Styles'!C5:C504,C18) -> 0 | E18: =SUMIFS('FW26 Styles'!P5:P504,'FW26 Styles'!A5:A504,A18,'FW26 Styles'!B5:B504,B18,'FW26 Styles'!C5:C504,C18) -> 0 | F18: =IF(D18=0,"",1-(E18/D18)) | G18: =SUMIFS('FW26 Styles'!O5:O504,'FW26 Styles'!A5:A504,A18,'FW26 Styles'!B5:B504,B18,'FW26 Styles'!C5:C504,C18) -> 0 | J18: =IF(H18=0,"",1-(I18/H18))
A19: Headwear | B19: Scarves | C19: Decorative | D19: =SUMIFS('FW26 Styles'!Q5:Q504,'FW26 Styles'!A5:A504,A19,'FW26 Styles'!B5:B504,B19,'FW26 Styles'!C5:C504,C19) -> 0 | E19: =SUMIFS('FW26 Styles'!P5:P504,'FW26 Styles'!A5:A504,A19,'FW26 Styles'!B5:B504,B19,'FW26 Styles'!C5:C504,C19) -> 0 | F19: =IF(D19=0,"",1-(E19/D19)) | G19: =SUMIFS('FW26 Styles'!O5:O504,'FW26 Styles'!A5:A504,A19,'FW26 Styles'!B5:B504,B19,'FW26 Styles'!C5:C504,C19) -> 0 | J19: =IF(H19=0,"",1-(I19/H19))
A20: Headwear | B20: Scarves | C20: New 1 | D20: =SUMIFS('FW26 Styles'!Q5:Q504,'FW26 Styles'!A5:A504,A20,'FW26 Styles'!B5:B504,B20,'FW26 Styles'!C5:C504,C20) -> 0 | E20: =SUMIFS('FW26 Styles'!P5:P504,'FW26 Styles'!A5:A504,A20,'FW26 Styles'!B5:B504,B20,'FW26 Styles'!C5:C504,C20) -> 0 | F20: =IF(D20=0,"",1-(E20/D20)) | G20: =SUMIFS('FW26 Styles'!O5:O504,'FW26 Styles'!A5:A504,A20,'FW26 Styles'!B5:B504,B20,'FW26 Styles'!C5:C504,C20) -> 0 | J20: =IF(H20=0,"",1-(I20/H20))
A21: Headwear | B21: Scarves | C21: New 2 | D21: =SUMIFS('FW26 Styles'!Q5:Q504,'FW26 Styles'!A5:A504,A21,'FW26 Styles'!B5:B504,B21,'FW26 Styles'!C5:C504,C21) -> 0 | E21: =SUMIFS('FW26 Styles'!P5:P504,'FW26 Styles'!A5:A504,A21,'FW26 Styles'!B5:B504,B21,'FW26 Styles'!C5:C504,C21) -> 0 | F21: =IF(D21=0,"",1-(E21/D21)) | G21: =SUMIFS('FW26 Styles'!O5:O504,'FW26 Styles'!A5:A504,A21,'FW26 Styles'!B5:B504,B21,'FW26 Styles'!C5:C504,C21) -> 0 | J21: =IF(H21=0,"",1-(I21/H21))
A22: Headwear | B22: Scarves | C22: New 3 | D22: =SUMIFS('FW26 Styles'!Q5:Q504,'FW26 Styles'!A5:A504,A22,'FW26 Styles'!B5:B504,B22,'FW26 Styles'!C5:C504,C22) -> 0 | E22: =SUMIFS('FW26 Styles'!P5:P504,'FW26 Styles'!A5:A504,A22,'FW26 Styles'!B5:B504,B22,'FW26 Styles'!C5:C504,C22) -> 0 | F22: =IF(D22=0,"",1-(E22/D22)) | G22: =SUMIFS('FW26 Styles'!O5:O504,'FW26 Styles'!A5:A504,A22,'FW26 Styles'!B5:B504,B22,'FW26 Styles'!C5:C504,C22) -> 0 | J22: =IF(H22=0,"",1-(I22/H22))
A23: Headwear | B23: Hijab | C23: Premium | D23: =SUMIFS('FW26 Styles'!Q5:Q504,'FW26 Styles'!A5:A504,A23,'FW26 Styles'!B5:B504,B23,'FW26 Styles'!C5:C504,C23) -> 0 | E23: =SUMIFS('FW26 Styles'!P5:P504,'FW26 Styles'!A5:A504,A23,'FW26 Styles'!B5:B504,B23,'FW26 Styles'!C5:C504,C23) -> 0 | F23: =IF(D23=0,"",1-(E23/D23)) | G23: =SUMIFS('FW26 Styles'!O5:O504,'FW26 Styles'!A5:A504,A23,'FW26 Styles'!B5:B504,B23,'FW26 Styles'!C5:C504,C23) -> 0 | J23: =IF(H23=0,"",1-(I23/H23))
A24: Headwear | B24: Hijab | C24: Bamboo | D24: =SUMIFS('FW26 Styles'!Q5:Q504,'FW26 Styles'!A5:A504,A24,'FW26 Styles'!B5:B504,B24,'FW26 Styles'!C5:C504,C24) -> 0 | E24: =SUMIFS('FW26 Styles'!P5:P504,'FW26 Styles'!A5:A504,A24,'FW26 Styles'!B5:B504,B24,'FW26 Styles'!C5:C504,C24) -> 0 | F24: =IF(D24=0,"",1-(E24/D24)) | G24: =SUMIFS('FW26 Styles'!O5:O504,'FW26 Styles'!A5:A504,A24,'FW26 Styles'!B5:B504,B24,'FW26 Styles'!C5:C504,C24) -> 0 | J24: =IF(H24=0,"",1-(I24/H24))
A25: Headwear | B25: Hijab | C25: Breathable | D25: =SUMIFS('FW26 Styles'!Q5:Q504,'FW26 Styles'!A5:A504,A25,'FW26 Styles'!B5:B504,B25,'FW26 Styles'!C5:C504,C25) -> 0 | E25: =SUMIFS('FW26 Styles'!P5:P504,'FW26 Styles'!A5:A504,A25,'FW26 Styles'!B5:B504,B25,'FW26 Styles'!C5:C504,C25) -> 0 | F25: =IF(D25=0,"",1-(E25/D25)) | G25: =SUMIFS('FW26 Styles'!O5:O504,'FW26 Styles'!A5:A504,A25,'FW26 Styles'!B5:B504,B25,'FW26 Styles'!C5:C504,C25) -> 0 | J25: =IF(H25=0,"",1-(I25/H25))
A26: Headwear | B26: Hijab | C26: New 1 | D26: =SUMIFS('FW26 Styles'!Q5:Q504,'FW26 Styles'!A5:A504,A26,'FW26 Styles'!B5:B504,B26,'FW26 Styles'!C5:C504,C26) -> 0 | E26: =SUMIFS('FW26 Styles'!P5:P504,'FW26 Styles'!A5:A504,A26,'FW26 Styles'!B5:B504,B26,'FW26 Styles'!C5:C504,C26) -> 0 | F26: =IF(D26=0,"",1-(E26/D26)) | G26: =SUMIFS('FW26 Styles'!O5:O504,'FW26 Styles'!A5:A504,A26,'FW26 Styles'!B5:B504,B26,'FW26 Styles'!C5:C504,C26) -> 0 | J26: =IF(H26=0,"",1-(I26/H26))
A27: Headwear | B27: Hijab | C27: New 2 | D27: =SUMIFS('FW26 Styles'!Q5:Q504,'FW26 Styles'!A5:A504,A27,'FW26 Styles'!B5:B504,B27,'FW26 Styles'!C5:C504,C27) -> 0 | E27: =SUMIFS('FW26 Styles'!P5:P504,'FW26 Styles'!A5:A504,A27,'FW26 Styles'!B5:B504,B27,'FW26 Styles'!C5:C504,C27) -> 0 | F27: =IF(D27=0,"",1-(E27/D27)) | G27: =SUMIFS('FW26 Styles'!O5:O504,'FW26 Styles'!A5:A504,A27,'FW26 Styles'!B5:B504,B27,'FW26 Styles'!C5:C504,C27) -> 0 | J27: =IF(H27=0,"",1-(I27/H27))
A28: Headwear | B28: Hijab | C28: New 3 | D28: =SUMIFS('FW26 Styles'!Q5:Q504,'FW26 Styles'!A5:A504,A28,'FW26 Styles'!B5:B504,B28,'FW26 Styles'!C5:C504,C28) -> 0 | E28: =SUMIFS('FW26 Styles'!P5:P504,'FW26 Styles'!A5:A504,A28,'FW26 Styles'!B5:B504,B28,'FW26 Styles'!C5:C504,C28) -> 0 | F28: =IF(D28=0,"",1-(E28/D28)) | G28: =SUMIFS('FW26 Styles'!O5:O504,'FW26 Styles'!A5:A504,A28,'FW26 Styles'!B5:B504,B28,'FW26 Styles'!C5:C504,C28) -> 0 | J28: =IF(H28=0,"",1-(I28/H28))
A29: Headwear | B29: Khimaar | C29: Premium | D29: =SUMIFS('FW26 Styles'!Q5:Q504,'FW26 Styles'!A5:A504,A29,'FW26 Styles'!B5:B504,B29,'FW26 Styles'!C5:C504,C29) -> 0 | E29: =SUMIFS('FW26 Styles'!P5:P504,'FW26 Styles'!A5:A504,A29,'FW26 Styles'!B5:B504,B29,'FW26 Styles'!C5:C504,C29) -> 0 | F29: =IF(D29=0,"",1-(E29/D29)) | G29: =SUMIFS('FW26 Styles'!O5:O504,'FW26 Styles'!A5:A504,A29,'FW26 Styles'!B5:B504,B29,'FW26 Styles'!C5:C504,C29) -> 0 | J29: =IF(H29=0,"",1-(I29/H29))
A30: Headwear | B30: Khimaar | C30: Bamboo | D30: =SUMIFS('FW26 Styles'!Q5:Q504,'FW26 Styles'!A5:A504,A30,'FW26 Styles'!B5:B504,B30,'FW26 Styles'!C5:C504,C30) -> 0 | E30: =SUMIFS('FW26 Styles'!P5:P504,'FW26 Styles'!A5:A504,A30,'FW26 Styles'!B5:B504,B30,'FW26 Styles'!C5:C504,C30) -> 0 | F30: =IF(D30=0,"",1-(E30/D30)) | G30: =SUMIFS('FW26 Styles'!O5:O504,'FW26 Styles'!A5:A504,A30,'FW26 Styles'!B5:B504,B30,'FW26 Styles'!C5:C504,C30) -> 0 | J30: =IF(H30=0,"",1-(I30/H30))
A31: Headwear | B31: Khimaar | C31: Breathable | D31: =SUMIFS('FW26 Styles'!Q5:Q504,'FW26 Styles'!A5:A504,A31,'FW26 Styles'!B5:B504,B31,'FW26 Styles'!C5:C504,C31) -> 0 | E31: =SUMIFS('FW26 Styles'!P5:P504,'FW26 Styles'!A5:A504,A31,'FW26 Styles'!B5:B504,B31,'FW26 Styles'!C5:C504,C31) -> 0 | F31: =IF(D31=0,"",1-(E31/D31)) | G31: =SUMIFS('FW26 Styles'!O5:O504,'FW26 Styles'!A5:A504,A31,'FW26 Styles'!B5:B504,B31,'FW26 Styles'!C5:C504,C31) -> 0 | J31: =IF(H31=0,"",1-(I31/H31))
A32: Headwear | B32: Khimaar | C32: New 1 | D32: =SUMIFS('FW26 Styles'!Q5:Q504,'FW26 Styles'!A5:A504,A32,'FW26 Styles'!B5:B504,B32,'FW26 Styles'!C5:C504,C32) -> 0 | E32: =SUMIFS('FW26 Styles'!P5:P504,'FW26 Styles'!A5:A504,A32,'FW26 Styles'!B5:B504,B32,'FW26 Styles'!C5:C504,C32) -> 0 | F32: =IF(D32=0,"",1-(E32/D32)) | G32: =SUMIFS('FW26 Styles'!O5:O504,'FW26 Styles'!A5:A504,A32,'FW26 Styles'!B5:B504,B32,'FW26 Styles'!C5:C504,C32) -> 0 | J32: =IF(H32=0,"",1-(I32/H32))
A33: Headwear | B33: Khimaar | C33: New 2 | D33: =SUMIFS('FW26 Styles'!Q5:Q504,'FW26 Styles'!A5:A504,A33,'FW26 Styles'!B5:B504,B33,'FW26 Styles'!C5:C504,C33) -> 0 | E33: =SUMIFS('FW26 Styles'!P5:P504,'FW26 Styles'!A5:A504,A33,'FW26 Styles'!B5:B504,B33,'FW26 Styles'!C5:C504,C33) -> 0 | F33: =IF(D33=0,"",1-(E33/D33)) | G33: =SUMIFS('FW26 Styles'!O5:O504,'FW26 Styles'!A5:A504,A33,'FW26 Styles'!B5:B504,B33,'FW26 Styles'!C5:C504,C33) -> 0 | J33: =IF(H33=0,"",1-(I33/H33))
A34: Headwear | B34: Khimaar | C34: New 3 | D34: =SUMIFS('FW26 Styles'!Q5:Q504,'FW26 Styles'!A5:A504,A34,'FW26 Styles'!B5:B504,B34,'FW26 Styles'!C5:C504,C34) -> 0 | E34: =SUMIFS('FW26 Styles'!P5:P504,'FW26 Styles'!A5:A504,A34,'FW26 Styles'!B5:B504,B34,'FW26 Styles'!C5:C504,C34) -> 0 | F34: =IF(D34=0,"",1-(E34/D34)) | G34: =SUMIFS('FW26 Styles'!O5:O504,'FW26 Styles'!A5:A504,A34,'FW26 Styles'!B5:B504,B34,'FW26 Styles'!C5:C504,C34) -> 0 | J34: =IF(H34=0,"",1-(I34/H34))
A35: Clothing | B35: Dresses | C35: Casual | D35: =SUMIFS('FW26 Styles'!Q5:Q504,'FW26 Styles'!A5:A504,A35,'FW26 Styles'!B5:B504,B35,'FW26 Styles'!C5:C504,C35) -> 0 | E35: =SUMIFS('FW26 Styles'!P5:P504,'FW26 Styles'!A5:A504,A35,'FW26 Styles'!B5:B504,B35,'FW26 Styles'!C5:C504,C35) -> 0 | F35: =IF(D35=0,"",1-(E35/D35)) | G35: =SUMIFS('FW26 Styles'!O5:O504,'FW26 Styles'!A5:A504,A35,'FW26 Styles'!B5:B504,B35,'FW26 Styles'!C5:C504,C35) -> 0 | J35: =IF(H35=0,"",1-(I35/H35))
A36: Clothing | B36: Dresses | C36: Occasion | D36: =SUMIFS('FW26 Styles'!Q5:Q504,'FW26 Styles'!A5:A504,A36,'FW26 Styles'!B5:B504,B36,'FW26 Styles'!C5:C504,C36) -> 0 | E36: =SUMIFS('FW26 Styles'!P5:P504,'FW26 Styles'!A5:A504,A36,'FW26 Styles'!B5:B504,B36,'FW26 Styles'!C5:C504,C36) -> 0 | F36: =IF(D36=0,"",1-(E36/D36)) | G36: =SUMIFS('FW26 Styles'!O5:O504,'FW26 Styles'!A5:A504,A36,'FW26 Styles'!B5:B504,B36,'FW26 Styles'!C5:C504,C36) -> 0 | J36: =IF(H36=0,"",1-(I36/H36))
A37: Clothing | B37: Dresses | C37: Essential | D37: =SUMIFS('FW26 Styles'!Q5:Q504,'FW26 Styles'!A5:A504,A37,'FW26 Styles'!B5:B504,B37,'FW26 Styles'!C5:C504,C37) -> 0 | E37: =SUMIFS('FW26 Styles'!P5:P504,'FW26 Styles'!A5:A504,A37,'FW26 Styles'!B5:B504,B37,'FW26 Styles'!C5:C504,C37) -> 0 | F37: =IF(D37=0,"",1-(E37/D37)) | G37: =SUMIFS('FW26 Styles'!O5:O504,'FW26 Styles'!A5:A504,A37,'FW26 Styles'!B5:B504,B37,'FW26 Styles'!C5:C504,C37) -> 0 | J37: =IF(H37=0,"",1-(I37/H37))
A38: Clothing | B38: Dresses | C38: New 1 | D38: =SUMIFS('FW26 Styles'!Q5:Q504,'FW26 Styles'!A5:A504,A38,'FW26 Styles'!B5:B504,B38,'FW26 Styles'!C5:C504,C38) -> 0 | E38: =SUMIFS('FW26 Styles'!P5:P504,'FW26 Styles'!A5:A504,A38,'FW26 Styles'!B5:B504,B38,'FW26 Styles'!C5:C504,C38) -> 0 | F38: =IF(D38=0,"",1-(E38/D38)) | G38: =SUMIFS('FW26 Styles'!O5:O504,'FW26 Styles'!A5:A504,A38,'FW26 Styles'!B5:B504,B38,'FW26 Styles'!C5:C504,C38) -> 0 | J38: =IF(H38=0,"",1-(I38/H38))
A39: Clothing | B39: Dresses | C39: New 2 | D39: =SUMIFS('FW26 Styles'!Q5:Q504,'FW26 Styles'!A5:A504,A39,'FW26 Styles'!B5:B504,B39,'FW26 Styles'!C5:C504,C39) -> 0 | E39: =SUMIFS('FW26 Styles'!P5:P504,'FW26 Styles'!A5:A504,A39,'FW26 Styles'!B5:B504,B39,'FW26 Styles'!C5:C504,C39) -> 0 | F39: =IF(D39=0,"",1-(E39/D39)) | G39: =SUMIFS('FW26 Styles'!O5:O504,'FW26 Styles'!A5:A504,A39,'FW26 Styles'!B5:B504,B39,'FW26 Styles'!C5:C504,C39) -> 0 | J39: =IF(H39=0,"",1-(I39/H39))
A40: Clothing | B40: Dresses | C40: New 3 | D40: =SUMIFS('FW26 Styles'!Q5:Q504,'FW26 Styles'!A5:A504,A40,'FW26 Styles'!B5:B504,B40,'FW26 Styles'!C5:C504,C40) -> 0 | E40: =SUMIFS('FW26 Styles'!P5:P504,'FW26 Styles'!A5:A504,A40,'FW26 Styles'!B5:B504,B40,'FW26 Styles'!C5:C504,C40) -> 0 | F40: =IF(D40=0,"",1-(E40/D40)) | G40: =SUMIFS('FW26 Styles'!O5:O504,'FW26 Styles'!A5:A504,A40,'FW26 Styles'!B5:B504,B40,'FW26 Styles'!C5:C504,C40) -> 0 | J40: =IF(H40=0,"",1-(I40/H40))
A41: Clothing | B41: Tops | C41: Blouse | D41: =SUMIFS('FW26 Styles'!Q5:Q504,'FW26 Styles'!A5:A504,A41,'FW26 Styles'!B5:B504,B41,'FW26 Styles'!C5:C504,C41) -> 0 | E41: =SUMIFS('FW26 Styles'!P5:P504,'FW26 Styles'!A5:A504,A41,'FW26 Styles'!B5:B504,B41,'FW26 Styles'!C5:C504,C41) -> 0 | F41: =IF(D41=0,"",1-(E41/D41)) | G41: =SUMIFS('FW26 Styles'!O5:O504,'FW26 Styles'!A5:A504,A41,'FW26 Styles'!B5:B504,B41,'FW26 Styles'!C5:C504,C41) -> 0 | J41: =IF(H41=0,"",1-(I41/H41))
A42: Clothing | B42: Tops | C42: LS Tops | D42: =SUMIFS('FW26 Styles'!Q5:Q504,'FW26 Styles'!A5:A504,A42,'FW26 Styles'!B5:B504,B42,'FW26 Styles'!C5:C504,C42) -> 0 | E42: =SUMIFS('FW26 Styles'!P5:P504,'FW26 Styles'!A5:A504,A42,'FW26 Styles'!B5:B504,B42,'FW26 Styles'!C5:C504,C42) -> 0 | F42: =IF(D42=0,"",1-(E42/D42)) | G42: =SUMIFS('FW26 Styles'!O5:O504,'FW26 Styles'!A5:A504,A42,'FW26 Styles'!B5:B504,B42,'FW26 Styles'!C5:C504,C42) -> 0 | J42: =IF(H42=0,"",1-(I42/H42))
A43: Clothing | B43: Tops | C43: LS Tees | D43: =SUMIFS('FW26 Styles'!Q5:Q504,'FW26 Styles'!A5:A504,A43,'FW26 Styles'!B5:B504,B43,'FW26 Styles'!C5:C504,C43) -> 0 | E43: =SUMIFS('FW26 Styles'!P5:P504,'FW26 Styles'!A5:A504,A43,'FW26 Styles'!B5:B504,B43,'FW26 Styles'!C5:C504,C43) -> 0 | F43: =IF(D43=0,"",1-(E43/D43)) | G43: =SUMIFS('FW26 Styles'!O5:O504,'FW26 Styles'!A5:A504,A43,'FW26 Styles'!B5:B504,B43,'FW26 Styles'!C5:C504,C43) -> 0 | J43: =IF(H43=0,"",1-(I43/H43))
...
